Workbook

Sheet Instructions
A1: @dropdown
B2: General Instructions for Use of Budget and Planning for HVAC and Plumbing Contractors
C4: Rules for Use:
D5: 1. Yellow means a place for user to enter data and it is required
D7: 2. Light blue means data has been entered once, and the software has exported it to this space.
D8: Light blue is a place for the user to decide if they want to make edits or changes based on
D9: each month, since some months may vary from yearly totals. The software allows the option.
D10: Leave the light blue and this uses a yearly figure. Change it monthly only in light blue areas.
D12: 3.Purple is calculated data that helps planning
D14: 4. Calculated data - If changed may not calculate in others cells
D16: 5. Unlocked calculated cells for you to adjust as needed
D18: 6. You can always change anything you like - it is a program that is formatted to be open for changes.
E19: a. Each page is locked and formatted for input in Yellow cells and adjustment in Green cells. No password is required to unlock
C20: Tips and Notes:
D22: 1. Before making any changes, save as a working model
D23: 2. Use Input Data Page to make changes to monthly budgets
D24: 3. Record daily revenue generaton in monthly tabs (optional)
E25: a. Can be recorded daily or weekly

Sheet Break-even
B2: Input Required in Yellow Boxes ONLY
B3: Plan Start Date
B4: 46023 | C4: Enter rolling 12 months numbers here
B5: Current Year to Date Sales Volume | C5: 1722955 | E5: Days in Year to Cover Overhead | F5: Date when Company Covers all Overhead
B7: Current Year to Date Overhead $ Amount | C7: 400594 | E7: =(C13/C27)+((7-C25)*C23) -> 268.3306 | F7: =B4+E7 -> 46291.331
B9: Current Year to Date Gross Margin % | C9: 0.3154
B11: Number of Weeks for Preceding Numbers | C11: 52
B13: Sales Volume Break-Even Year-To-Date | C13: =C7/C9 -> 1270114.1
B15: Average Monthly $ Sales | C15: =(C5/C11)*4.3333 -> 143578.48
B17: Monthly Sales Volume Break-even | C17: =((C7/C11)*4.3333)/C9 -> 105842.03
B19: Average Weekly $ Sales | C19: =C5/C11 -> 33133.75
B21: Weekly Sales Volume Break-Even | C21: =(C7/C11)/(C9) -> 24425.272
B23: Average Break-Even Weeks for Period | C23: =C13/C19 -> 38.332943
B25: Average Days Worked per Week | C25: 5
B27: Average Daily Sales Volume | C27: =C19/C25 -> 6626.75
B29: Sales Volume Break-Even Per Day | C29: =C21/C25 -> 4885.0544

Sheet Budget
C1: Input Required in Yellow Boxes ONLY
B3: Current Year to Date Sales Volume | C3: ='Break-even'!C5 -> 1722955 | E3: Net Profit Desired Above Break-even
E4: 350000
E6: New $ Overhead Amount | F6: Additional Salaries including owner to be added to Overhead | G6: Additional Marketing $s to be added to Overhead | H6: Additional $ Insurance Cost to be added to Overhead | I6: Additional $ for Promotion Cost for Financing Buy-down, Give-Aways | J6: Additional cost of new direct cost employee ie., training, uniforms, etc. | K6: Cost of Depreciation for New Capital Investment | L6: Cost of Additional Third Party Services | M6: Additional $ Adjustment to OH. Increase by minimum of 3%
B7: Current Year to Date Overhead $ Amount | C7: ='Break-even'!C7 -> 400594 | E7: =C7+(F7+G7+H7+I7+J7+K7++L7+M7) -> 659594 | F7: 150000 | G7: 50000 | H7: 6000 | I7: 20000 | L7: 15000 | M7: 18000
E9: Overhead Comparison | F9: % Overhead to Previous Year's Revenue | G9: % Overhead to Budgeted Year's Revenue
F10: =C7/C3 -> 0.23250404 | G10: =E7/G17 -> 0.30052996
J11: Budget Start Date
E12: New Gross Margin %
B13: Current Year to Date Gross Margin % | C13: ='Break-even'!C9 -> 0.3154 | E13: 0.46 | J13: 46023
B15: Number of Weeks for Preceding Numbers | C15: ='Break-even'!C11 -> 52 | G15: New Sales Volume for Break-Even Plus Profit Goal + OH Adjustments Above | J15: Days in Year to Cover Overhead | K15: Date when Company Covers all Overhead
B17: Sales Volume Break-Even Year-To-Date | C17: =C7/C13 -> 1270114.1 | E17: =E7/E13 -> 1433900 | G17: =E17+(E4/E13) -> 2194769.6 | J17: =(E17/G36)+((7-C32)*G30) -> 237.81066 | K17: =J13+J17 -> 46260.811
G19: Average Monthly Sales Volume for Break-Even Plus Profit Goal + OH Adjustments Above
B21: Average Monthly $ Sales | C21: ='Break-even'!$C$15 -> 143578.48 | G21: =(G17/C15)*4.3333 -> 182896.06
B23: Monthly Sales Volume Break-even | C23: =((C7/C15)*4.3333)/C13 -> 105842.03 | E23: =((E7/C15)*4.3333)/E13 -> 119490.75 | G23: Average Weekly Sales Required to Achieve Break-even + Profit Goal + OH Adjustment
B26: Average Weekly Sales $ | C26: =C3/C15 -> 33133.75 | G26: =G17/C15 -> 42207.107
G27: Average Break-Even Weeks for Period
B28: Weekly Sales Volume Break-Even | C28: =(C7/C15)/(C13) -> 24425.272 | E28: =(E7/C15)/(E13) -> 27575
B30: Average Break-Even Weeks for Period | C30: =C17/C26 -> 38.332943 | G30: =E17/G26 -> 33.972952
G31: Average Daily Sales Required to Achieve Breakeven + Profit Goal + Overhead Adjustment
B32: Average Days Worked per Week | C32: ='Break-even'!C25 -> 5
B34: Average Daily Sales Volume | C34: =C26/C32 -> 6626.75
B36: Sales Volume Break-Even Per Day | C36: =C28/C32 -> 4885.0544 | E36: =E28/C32 -> 5515 | G36: =G26/C32 -> 8441.4214

Sheet Sales Goals
B1: Input Required in Yellow Boxes ONLY
F2: STEP 1
B3: Sales Volume Required to Break-Even by Month | F3: Input 3 year historical data in Yellow boxes in tables below* | K3: * If departmental sales numbers are not avaiable, put monthly totals in Install department
B4: =Budget!E23 -> 119490.75
B5: 3 Yr Seasonal index | F5: STEP 2 | H5: STEP 3
B7: Month | D7: Monthly Budget | F7: Compare Monthly Budgeted Sales Volume to Monthly Break-even Sales Volume. If Monthly Budgeted Sales Volume is Below Monthly Break-even, do one of two things: | H7: Adjustment in Sales Volume per Month based on Break-Even | I7: Final Budgeted Sales Volume by Month
B8: January | C8: =D27 -> 0.061824235 | D8: =(Budget!G17)*C8 -> 135689.95 | H8: 0 | I8: =D8+H8 -> 135689.95
B9: February | C9: =D28 -> 0.057375905 | D9: =(Budget!G17)*C9 -> 125926.89 | H9: 0 | I9: =D9+H9 -> 125926.89
B10: March | C10: =D29 -> 0.044134422 | D10: =(Budget!G17)*C10 -> 96864.886 | H10: 0 | I10: =D10+H10 -> 96864.886
B11: April | C11: =D30 -> 0.085964919 | D11: =(Budget!G17)*C11 -> 188673.19 | H11: 0 | I11: =D11+H11 -> 188673.19
B12: May | C12: =D31 -> 0.088370321 | D12: =(Budget!G17)*C12 -> 193952.49 | H12: 0 | I12: =D12+H12 -> 193952.49
B13: June | C13: =D32 -> 0.096416606 | D13: =(Budget!G17)*C13 -> 211612.23 | F13: 1. Return to Budget Page and reduce budgeted projections of overhead or increase gross margin % | H13: 0 | I13: =D13+H13 -> 211612.23
B14: July | C14: =D33 -> 0.12195645 | D14: =(Budget!G17)*C14 -> 267666.3 | H14: 0 | I14: =D14+H14 -> 267666.3
B15: August | C15: =D34 -> 0.14795192 | D15: =(Budget!G17)*C15 -> 324720.38 | H15: 0 | I15: =D15+H15 -> 324720.38
B16: September | C16: =D35 -> 0.086812654 | D16: =(Budget!G17)*C16 -> 190533.77 | H16: 0 | I16: =D16+H16 -> 190533.77
B17: October | C17: =D36 -> 0.076930656 | D17: =(Budget!G17)*C17 -> 168845.06 | H17: 0 | I17: =D17+H17 -> 168845.06
B18: November | C18: =D37 -> 0.069492571 | D18: =(Budget!G17)*C18 -> 152520.18 | F18: 2. Increase sales in column "G" to Break-even Amount from "B3" | H18: 0 | I18: =D18+H18 -> 152520.18
B19: December | C19: =D38 -> 0.062769338 | D19: =(Budget!G17)*C19 -> 137764.23 | H19: 0 | I19: =D19+H19 -> 137764.23
C20: =SUM(C8:C19) -> 1 | D20: =SUM(D8:D19) -> 2194769.6 | I20: =SUM(I8:I19) -> 2194769.6
J24: Historical Revenue
C25: 3 Year Historical Seasonal Index | J25: 2023 | O25: 2024 | T25: 2025 | Y25: Historical 3 Year Total
D26: Total | E26: Install | F26: Service/Maint | G26: Plumbing | J26: Total | K26: Install | L26: Service/Maint | M26: Plumbing | O26: Total | P26: Install | Q26: Service/Maint | R26: Plumbing | T26: Total | U26: Install | V26: Service/Maint | W26: Plumbing | Y26: Total | Z26: Install | AA26: Service/Maint | AB26: Plumbing
C27: Jan | D27: =Y27/$Y$39 -> 0.061824235 | E27: =Z27/$Z$39 -> 0.06330255 | F27: =AA27/$AA$39 -> 0.063720812 | G27: =AB27/$AB$39 -> 0 | I27: Jan | J27: =K27+L27+M27 -> 97104 | K27: 71701 | L27: 25403 | M27: 0 | O27: =P27+Q27+R27 -> 121948 | P27: 90858 | Q27: 31090 | T27: =U27+V27+W27 -> 85571 | U27: 57527 | V27: 28044 | Y27: =Z27+AA27+AB27 -> 304623 | Z27: =U27+P27+K27 -> 220086 | AA27: =V27+Q27+L27 -> 84537 | AB27: =W27+R27+M27 -> 0
C28: Feb | D28: =Y28/$Y$39 -> 0.057375905 | E28: =Z28/$Z$39 -> 0.058677517 | F28: =AA28/$AA$39 -> 0.059320348 | G28: =AB28/$AB$39 -> 0 | I28: Feb | J28: =K28+L28+M28 -> 98987 | K28: 62516 | L28: 36471 | O28: =P28+Q28+R28 -> 85950 | P28: 67745 | Q28: 18205 | T28: =U28+V28+W28 -> 97768 | U28: 73745 | V28: 24023 | Y28: =Z28+AA28+AB28 -> 282705 | Z28: =U28+P28+K28 -> 204006 | AA28: =V28+Q28+L28 -> 78699 | AB28: =W28+R28+M28 -> 0
C29: March | D29: =Y29/$Y$39 -> 0.044134422 | E29: =Z29/$Z$39 -> 0.04598974 | F29: =AA29/$AA$39 -> 0.04339184 | G29: =AB29/$AB$39 -> 0 | I29: March | J29: =K29+L29+M29 -> 85719 | K29: 55309 | L29: 30410 | O29: =P29+Q29+R29 -> 65701 | P29: 52865 | Q29: 12836 | T29: =U29+V29+W29 -> 66041 | U29: 51720 | V29: 14321 | Y29: =Z29+AA29+AB29 -> 217461 | Z29: =U29+P29+K29 -> 159894 | AA29: =V29+Q29+L29 -> 57567 | AB29: =W29+R29+M29 -> 0
C30: April | D30: =Y30/$Y$39 -> 0.085964919 | E30: =Z30/$Z$39 -> 0.097352054 | F30: =AA30/$AA$39 -> 0.064147442 | G30: =AB30/$AB$39 -> 0 | I30: April | J30: =K30+L30+M30 -> 121529 | K30: 96935 | L30: 24594 | O30: =P30+Q30+R30 -> 149577 | P30: 121009 | Q30: 28568 | T30: =U30+V30+W30 -> 152464 | U30: 120523 | V30: 31941 | Y30: =Z30+AA30+AB30 -> 423570 | Z30: =U30+P30+K30 -> 338467 | AA30: =V30+Q30+L30 -> 85103 | AB30: =W30+R30+M30 -> 0
C31: May | D31: =Y31/$Y$39 -> 0.088370321 | E31: =Z31/$Z$39 -> 0.082233258 | F31: =AA31/$AA$39 -> 0.1127018 | G31: =AB31/$AB$39 -> 0 | I31: May | J31: =K31+L31+M31 -> 128636 | K31: 88749 | L31: 39887 | O31: =P31+Q31+R31 -> 94821 | P31: 40940 | Q31: 53881 | T31: =U31+V31+W31 -> 211965 | U31: 156214 | V31: 55751 | Y31: =Z31+AA31+AB31 -> 435422 | Z31: =U31+P31+K31 -> 285903 | AA31: =V31+Q31+L31 -> 149519 | AB31: =W31+R31+M31 -> 0
C32: June | D32: =Y32/$Y$39 -> 0.096416606 | E32: =Z32/$Z$39 -> 0.056566914 | F32: =AA32/$AA$39 -> 0.20984745 | G32: =AB32/$AB$39 -> 0 | I32: June | J32: =K32+L32+M32 -> 70076 | K32: 29355 | L32: 40721 | O32: =P32+Q32+R32 -> 246117 | P32: 53006 | Q32: 193111 | T32: =U32+V32+W32 -> 158875 | U32: 114307 | V32: 44568 | Y32: =Z32+AA32+AB32 -> 475068 | Z32: =U32+P32+K32 -> 196668 | AA32: =V32+Q32+L32 -> 278400 | AB32: =W32+R32+M32 -> 0
C33: July | D33: =Y33/$Y$39 -> 0.12195645 | E33: =Z33/$Z$39 -> 0.12945404 | F33: =AA33/$AA$39 -> 0.11369149 | G33: =AB33/$AB$39 -> 0 | I33: July | J33: =K33+L33+M33 -> 141904 | K33: 96322 | L33: 45582 | O33: =P33+Q33+R33 -> 253845 | P33: 199484 | Q33: 54361 | T33: =U33+V33+W33 -> 205160 | U33: 154271 | V33: 50889 | Y33: =Z33+AA33+AB33 -> 600909 | Z33: =U33+P33+K33 -> 450077 | AA33: =V33+Q33+L33 -> 150832 | AB33: =W33+R33+M33 -> 0
C34: August | D34: =Y34/$Y$39 -> 0.14795192 | E34: =Z34/$Z$39 -> 0.17725698 | F34: =AA34/$AA$39 -> 0.084964098 | G34: =AB34/$AB$39 -> 0 | I34: August | J34: =K34+L34+M34 -> 192721 | K34: 157605 | L34: 35116 | O34: =P34+Q34+R34 -> 240439 | P34: 193633 | Q34: 46806 | T34: =U34+V34+W34 -> 295835 | U34: 265037 | V34: 30798 | Y34: =Z34+AA34+AB34 -> 728995 | Z34: =U34+P34+K34 -> 616275 | AA34: =V34+Q34+L34 -> 112720 | AB34: =W34+R34+M34 -> 0
C35: Sept | D35: =Y35/$Y$39 -> 0.086812654 | E35: =Z35/$Z$39 -> 0.092699409 | F35: =AA35/$AA$39 -> 0.079488768 | G35: =AB35/$AB$39 -> 0 | I35: Sept | J35: =K35+L35+M35 -> 139207 | K35: 102271 | L35: 36936 | O35: =P35+Q35+R35 -> 138416 | P35: 102562 | Q35: 35854 | T35: =U35+V35+W35 -> 150124 | U35: 117458 | V35: 32666 | Y35: =Z35+AA35+AB35 -> 427747 | Z35: =U35+P35+K35 -> 322291 | AA35: =V35+Q35+L35 -> 105456 | AB35: =W35+R35+M35 -> 0
C36: Oct | D36: =Y36/$Y$39 -> 0.076930656 | E36: =Z36/$Z$39 -> 0.088955951 | F36: =AA36/$AA$39 -> 0.052597541 | G36: =AB36/$AB$39 -> 0 | I36: Oct | J36: =K36+L36+M36 -> 164977 | K36: 146272 | L36: 18705 | O36: =P36+Q36+R36 -> 136756 | P36: 101183 | Q36: 35573 | T36: =U36+V36+W36 -> 77323 | U36: 61821 | V36: 15502 | Y36: =Z36+AA36+AB36 -> 379056 | Z36: =U36+P36+K36 -> 309276 | AA36: =V36+Q36+L36 -> 69780 | AB36: =W36+R36+M36 -> 0
C37: Nov | D37: =Y37/$Y$39 -> 0.069492571 | E37: =Z37/$Z$39 -> 0.057861808 | F37: =AA37/$AA$39 -> 0.065462757 | G37: 0 | I37: Nov | J37: =K37+L37+M37 -> 107712 | K37: 66072 | L37: 41640 | O37: =P37+Q37+R37 -> 89452 | P37: 59157 | Q37: 30295 | T37: =U37+V37+W37 -> 145242.75 | U37: 75941 | V37: 14913 | W37: 54388.75 | Y37: =Z37+AA37+AB37 -> 342406.75 | Z37: =U37+P37+K37 -> 201170 | AA37: =V37+Q37+L37 -> 86848 | AB37: =W37+R37+M37 -> 54388.75
C38: Dec | D38: =Y38/$Y$39 -> 0.062769338 | E38: =Z38/$Z$39 -> 0.049649786 | F38: =AA38/$AA$39 -> 0.050665648 | G38: 0 | I38: Dec | J38: =K38+L38+M38 -> 40000 | K38: 20000 | L38: 20000 | O38: =P38+Q38+R38 -> 99836 | P38: 67619 | Q38: 32217 | T38: =U38+V38+W38 -> 169443.75 | U38: 85000 | V38: 15000 | W38: 69443.75 | Y38: =Z38+AA38+AB38 -> 309279.75 | Z38: =U38+P38+K38 -> 172619 | AA38: =V38+Q38+L38 -> 67217 | AB38: =W38+R38+M38 -> 69443.75
D39: =SUM(D27:D38) -> 1 | E39: =SUM(E27:E38) -> 1 | F39: =SUM(F27:F38) -> 1 | G39: =SUM(G27:G38) -> 0 | J39: =K39+L39+M39 -> 1388572 | K39: =SUM(K27:K38) -> 993107 | L39: =SUM(L27:L38) -> 395465 | M39: =SUM(M27:M38) -> 0 | O39: =P39+Q39+R39 -> 1722858 | P39: =SUM(P27:P38) -> 1150061 | Q39: =SUM(Q27:Q38) -> 572797 | R39: =SUM(R27:R38) -> 0 | T39: =U39+V39+W39 -> 1815812.5 | U39: =SUM(U27:U38) -> 1333564 | V39: =SUM(V27:V38) -> 358416 | W39: =SUM(W27:W38) -> 123832.5 | Y39: =SUM(Y27:Y38) -> 4927242.5 | Z39: =SUM(Z27:Z38) -> 3476732 | AA39: =SUM(AA27:AA38) -> 1326678 | AB39: =SUM(AB27:AB38) -> 123832.5
C40: Annual historical Dept % | E40: =Z39/Y39 -> 0.70561414 | F40: =AA39/Y39 -> 0.26925364 | G40: =AB39/Y39 -> 0.025132211
C41: 2026 department budget | E41: =E40*D20 -> 1548660.4 | F41: =F40*D20 -> 590949.7 | G41: =G40*D20 -> 55159.413

Sheet Input Data
D2: Enter Monthly Targets | Q2: Target Annual Average (based on monthly input) | S2: 3 year historical Revenue Split average*
D4: January | E4: February | F4: March | G4: April | H4: May | I4: June | J4: July | K4: August | L4: September | M4: October | N4: November | O4: December
B5: Revenue Split | Q5: Used for headcount calculator
C6: Install | D6: 0.64 | E6: 0.64 | F6: 0.64 | G6: 0.64 | H6: 0.64 | I6: 0.64 | J6: 0.64 | K6: 0.64 | L6: 0.64 | M6: 0.64 | N6: 0.64 | O6: 0.64 | Q6: =SUM(D6:O6)/12 -> 0.64 | S6: ='Sales Goals'!E40 -> 0.70561414
C7: Service | D7: 0.1 | E7: 0.09 | F7: 0.08 | G7: 0.1 | H7: 0.13 | I7: 0.13 | J7: 0.12 | K7: 0.11 | L7: 0.09 | M7: 0.08 | N7: 0.11 | O7: 0.12 | Q7: =SUM(D7:O7)/12 -> 0.105 | S7: ='Sales Goals'!F40 -> 0.26925364
C8: Maitenance | D8: 0.08 | E8: 0.09 | F8: 0.1 | G8: 0.08 | H8: 0.05 | I8: 0.05 | J8: 0.06 | K8: 0.07 | L8: 0.09 | M8: 0.1 | N8: 0.07 | O8: 0.06 | Q8: =SUM(D8:O8)/12 -> 0.075
C9: Plumbing | D9: 0.18 | E9: 0.18 | F9: 0.18 | G9: 0.18 | H9: 0.18 | I9: 0.18 | J9: 0.18 | K9: 0.18 | L9: 0.18 | M9: 0.18 | N9: 0.18 | O9: 0.18 | Q9: =SUM(D9:O9)/12 -> 0.18 | S9: ='Sales Goals'!G40 -> 0.025132211
C10: Total | D10: =SUM(D6:D9) -> 1 | E10: =SUM(E6:E9) -> 1 | F10: =SUM(F6:F9) -> 1 | G10: =SUM(G6:G9) -> 1 | H10: =SUM(H6:H9) -> 1 | I10: =SUM(I6:I9) -> 1 | J10: =SUM(J6:J9) -> 1 | K10: =SUM(K6:K9) -> 1 | ... O10: =SUM(O6:O9) -> 1
B11: Installation | S11: * From Historical data on Sales Goals page
C12: Opportunity Job Average | D12: 7000 | E12: 7500 | F12: 6000 | G12: 7500 | H12: 10000 | I12: 9000 | J12: 8500 | K12: 8500 | L12: 8500 | M12: 8500 | N12: 8500 | O12: 8500 | Q12: =SUM(D12:O12)/12 -> 8166.6667
C13: Sales Close % | D13: 0.5 | E13: 0.5 | F13: 0.5 | G13: 0.5 | H13: 0.5 | I13: 0.5 | J13: 0.5 | K13: 0.5 | L13: 0.5 | M13: 0.5 | N13: 0.5 | O13: 0.5 | Q13: =SUM(D13:O13)/12 -> 0.5
B15: Service
C16: Opportunity Job Average | D16: 325 | E16: 375 | F16: 375 | G16: 400 | H16: 450 | I16: 450 | J16: 425 | K16: 375 | L16: 350 | M16: 325 | N16: 400 | O16: 400 | Q16: =SUM(D16:O16)/12 -> 387.5
C17: Close % | D17: 1 | E17: 1 | F17: 1 | G17: 1 | H17: 1 | I17: 1 | J17: 1 | K17: 1 | L17: 1 | M17: 1 | N17: 1 | O17: 1 | Q17: =SUM(D17:O17)/12 -> 1
B19: Maintenance
C20: Opportunity Job Average | D20: 125 | E20: 125 | F20: 150 | G20: 150 | H20: 200 | I20: 200 | J20: 200 | K20: 175 | L20: 125 | M20: 125 | N20: 150 | O20: 150 | Q20: =SUM(D20:O20)/12 -> 156.25
C21: Close % | D21: 1 | E21: 1 | F21: 1 | G21: 1 | H21: 1 | I21: 1 | J21: 1 | K21: 1 | L21: 1 | M21: 1 | N21: 1 | O21: 1 | Q21: =SUM(D21:O21)/12 -> 1
B23: Plumbing
C24: Opportunity Job Average | D24: 750 | E24: 750 | F24: 750 | G24: 750 | H24: 750 | I24: 750 | J24: 750 | K24: 750 | L24: 750 | M24: 750 | N24: 750 | O24: 750 | Q24: =SUM(D24:O24)/12 -> 750
C25: Close % | D25: 1 | E25: 1 | F25: 1 | G25: 1 | H25: 1 | I25: 1 | J25: 1 | K25: 1 | L25: 1 | M25: 1 | N25: 1 | O25: 1 | Q25: =SUM(D25:O25)/12 -> 1
B28: Staffing
C29: Opps per day | E29: Days per month | G29: Capacity per person
C30: Sales | D30: 2.5 | E30: 22 | G30: =D30*E30 -> 55
C31: Service | D31: 3 | E31: 22 | G31: =D31*E31 -> 66
C32: maintenance | D32: 4.25 | E32: 22 | G32: =D32*E32 -> 93.5
C33: Plumbing | E33: 22 | G33: =D33*E33 -> 0
C34: Install | D34: 1 | E34: 22 | G34: =D34*E34 -> 22

Sheet January
A1: Tracking for Daily Break-Even and Sales - January | J1: Field Stafing
D2: Average Installation Ticket | F2: ='Input Data'!D12 -> 7000 | H2: # Opps Required | J2: Sales | K2: Service/Maint | L2: Plumbing | M2: Install
A3: Budgeted Monthly Sales Volume for Break-Even Plus Profit Goal + OH Adjustments Above | B3: ='Sales Goals'!I8 -> 135689.95 | D3: Monthly Installation Sales Goal | F3: =B3*B9 -> 86841.568 | G3: Closing % | H3: ='Input Data'!D13 -> 0.5
D4: # Installations Required this month | F4: =F3/F2 -> 12.405938 | H4: =F4/H3 -> 24.811877 | J4: =H4/'Input Data'!G30 -> 0.45112503 | M4: =F4/'Input Data'!G34 -> 0.56390629
A5: Average Daily Sales Required to Achieve Breakeven + Profit Goal + Overhead Adjustment | B5: =((B3/31)*7)/'Break-even'!C25 -> 6127.9332
D6: Service Opportunity Job Average | F6: ='Input Data'!D16 -> 325 | H6: Opp Calls Required
A7: Sales Volume Break-Even Per Day | B7: =Budget!C36 -> 4885.0544 | D7: Monthly Service Sales Goal | F7: =B3*B11 -> 13568.995 | G7: Closing % | H7: ='Input Data'!D17 -> 1
D8: # Service Tickets Required this month | F8: =F7/F6 -> 41.750754 | H8: =F8/H7 -> 41.750754 | K8: =H8/'Input Data'!G31 -> 0.63258718
A9: Percentage of Revenue for Install | B9: ='Input Data'!D6 -> 0.64
D10: Maintenance Opportunity Job Average | F10: ='Input Data'!D20 -> 125 | H10: Opp Calls Required
A11: Percentage of Revenue for Service | B11: ='Input Data'!D7 -> 0.1 | D11: Monthly Maintenance Sales Goal | F11: =B3*B13 -> 10855.196 | G11: Closing % | H11: ='Input Data'!D21 -> 1
D12: # Maintenance Tickets Required this month | F12: =F11/F10 -> 86.841568 | H12: =F12/H11 -> 86.841568 | K12: =H12/'Input Data'!G32 -> 0.92878682
A13: Percentage of Revenue for Maintenance | B13: ='Input Data'!D8 -> 0.08
D14: Plumbing Opportunity Job Average | F14: ='Input Data'!D24 -> 750 | H14: Opp Calls Required
A15: Percentage of Revenue for Plumbing | B15: ='Input Data'!D9 -> 0.18 | D15: Monthly Service Sales Goal | F15: =B3*B15 -> 24424.191 | G15: Closing % | H15: ='Input Data'!D25 -> 1
D16: # PlumbingTickets Required this month | F16: =F15/F14 -> 32.565588 | H16: =F16/H15 -> 32.565588 | L16: =H16/'Input Data'!G33 -> #DIV/0!
B18: Daily Service Goal | C18: Actual Service Revenue | D18: Daily Install Goal | E18: Actual Install Revenue | F18: Daily Maintenance Goal | G18: Actual Maintenance Sales | H18: Daily Plumbing Goal | I18: Actual Plumbing Revenue | J18: Sales Goal to Date | K18: Actual Sales to Date | L18: Difference Between Actual Sales & Budgeted Sales
A19: Day 1 | B19: =$B$5*$B$11 -> 612.79332 | C19: 0 | D19: =$B$5*$B$9 -> 3921.8773 | E19: 0 | F19: =$B$5*$B$13 -> 490.23466 | G19: 0 | H19: =$B$5*$B$15 -> 1103.028 | I19: 0 | J19: =B19+D19+F19+H19 -> 6127.9332 | K19: =C19+E19+G19+I19 -> 0 | L19: =J19-K19 -> 6127.9332
A20: Day 2 | B20: =$B$5*$B$11 -> 612.79332 | C20: 0 | D20: =$B$5*$B$9 -> 3921.8773 | E20: 0 | F20: =$B$5*$B$13 -> 490.23466 | G20: 0 | H20: =$B$5*$B$15 -> 1103.028 | I20: 0 | J20: =J19+B20+D20+F20+H20 -> 12255.866 | K20: =K19+C20+E20+G20+I20 -> 0 | L20: =J20-K20 -> 12255.866
A21: Day 3 | B21: =$B$5*$B$11 -> 612.79332 | C21: 0 | D21: =$B$5*$B$9 -> 3921.8773 | E21: 0 | F21: =$B$5*$B$13 -> 490.23466 | G21: 0 | H21: =$B$5*$B$15 -> 1103.028 | I21: 0 | J21: =J20+B21+D21+F21+H21 -> 18383.8 | K21: =K20+C21+E21+G21+I21 -> 0 | L21: =J21-K21 -> 18383.8
A22: Day 4 | B22: =$B$5*$B$11 -> 612.79332 | C22: 0 | D22: =$B$5*$B$9 -> 3921.8773 | E22: 0 | F22: =$B$5*$B$13 -> 490.23466 | G22: 0 | H22: =$B$5*$B$15 -> 1103.028 | I22: 0 | J22: =J21+B22+D22+F22+H22 -> 24511.733 | K22: =K21+C22+E22+G22+I22 -> 0 | L22: =J22-K22 -> 24511.733
A23: Day 5 | B23: =$B$5*$B$11 -> 612.79332 | C23: 0 | D23: =$B$5*$B$9 -> 3921.8773 | E23: 0 | F23: =$B$5*$B$13 -> 490.23466 | G23: 0 | H23: =$B$5*$B$15 -> 1103.028 | I23: 0 | J23: =J22+B23+D23+F23+H23 -> 30639.666 | K23: =K22+C23+E23+G23+I23 -> 0 | L23: =J23-K23 -> 30639.666
A24: Day 6 | B24: =$B$5*$B$11 -> 612.79332 | C24: 0 | D24: =$B$5*$B$9 -> 3921.8773 | E24: 0 | F24: =$B$5*$B$13 -> 490.23466 | G24: 0 | H24: =$B$5*$B$15 -> 1103.028 | I24: 0 | J24: =J23+B24+D24+F24+H24 -> 36767.599 | K24: =K23+C24+E24+G24+I24 -> 0 | L24: =J24-K24 -> 36767.599
A25: Day 7 | B25: =$B$5*$B$11 -> 612.79332 | C25: 0 | D25: =$B$5*$B$9 -> 3921.8773 | E25: 0 | F25: =$B$5*$B$13 -> 490.23466 | G25: 0 | H25: =$B$5*$B$15 -> 1103.028 | I25: 0 | J25: =J24+B25+D25+F25+H25 -> 42895.533 | K25: =K24+C25+E25+G25+I25 -> 0 | L25: =J25-K25 -> 42895.533
A26: Day 8 | B26: =$B$5*$B$11 -> 612.79332 | C26: 0 | D26: =$B$5*$B$9 -> 3921.8773 | E26: 0 | F26: =$B$5*$B$13 -> 490.23466 | G26: 0 | H26: =$B$5*$B$15 -> 1103.028 | I26: 0 | J26: =J25+B26+D26+F26+H26 -> 49023.466 | K26: =K25+C26+E26+G26+I26 -> 0 | L26: =J26-K26 -> 49023.466
A27: Day 9 | B27: =$B$5*$B$11 -> 612.79332 | C27: 0 | D27: =$B$5*$B$9 -> 3921.8773 | E27: 0 | F27: =$B$5*$B$13 -> 490.23466 | G27: 0 | H27: =$B$5*$B$15 -> 1103.028 | I27: 0 | J27: =J26+B27+D27+F27+H27 -> 55151.399 | K27: =K26+C27+E27+G27+I27 -> 0 | L27: =J27-K27 -> 55151.399
A28: Day 10 | B28: =$B$5*$B$11 -> 612.79332 | C28: 0 | D28: =$B$5*$B$9 -> 3921.8773 | E28: 0 | F28: =$B$5*$B$13 -> 490.23466 | G28: 0 | H28: =$B$5*$B$15 -> 1103.028 | I28: 0 | J28: =J27+B28+D28+F28+H28 -> 61279.332 | K28: =K27+C28+E28+G28+I28 -> 0 | L28: =J28-K28 -> 61279.332
A29: Day 11 | B29: =$B$5*$B$11 -> 612.79332 | C29: 0 | D29: =$B$5*$B$9 -> 3921.8773 | E29: 0 | F29: =$B$5*$B$13 -> 490.23466 | G29: 0 | H29: =$B$5*$B$15 -> 1103.028 | I29: 0 | J29: =J28+B29+D29+F29+H29 -> 67407.266 | K29: =K28+C29+E29+G29+I29 -> 0 | L29: =J29-K29 -> 67407.266
A30: Day 12 | B30: =$B$5*$B$11 -> 612.79332 | C30: 0 | D30: =$B$5*$B$9 -> 3921.8773 | E30: 0 | F30: =$B$5*$B$13 -> 490.23466 | G30: 0 | H30: =$B$5*$B$15 -> 1103.028 | I30: 0 | J30: =J29+B30+D30+F30+H30 -> 73535.199 | K30: =K29+C30+E30+G30+I30 -> 0 | L30: =J30-K30 -> 73535.199
A31: Day 13 | B31: =$B$5*$B$11 -> 612.79332 | C31: 0 | D31: =$B$5*$B$9 -> 3921.8773 | E31: 0 | F31: =$B$5*$B$13 -> 490.23466 | G31: 0 | H31: =$B$5*$B$15 -> 1103.028 | I31: 0 | J31: =J30+B31+D31+F31+H31 -> 79663.132 | K31: =K30+C31+E31+G31+I31 -> 0 | L31: =J31-K31 -> 79663.132
... A45: Day 27 | B45: =$B$5*$B$11 -> 612.79332 | C45: 0 | D45: =$B$5*$B$9 -> 3921.8773 | E45: 0 | F45: =$B$5*$B$13 -> 490.23466 | G45: 0 | H45: =$B$5*$B$15 -> 1103.028 | I45: 0 | J45: =J44+B45+D45+F45+H45 -> 165454.2 | K45: =K44+C45+E45+G45+I45 -> 0 | L45: =J45-K45 -> 165454.2
A48: ACTION PLANS | C48: Budgeted Cost | D48: Start Date | E48: Completion Date | F48: Who Responsible

Sheet February
A1: Tracking for Daily Break-Even and Sales - February | J1: Field Stafing
D2: Average Installation Ticket | F2: ='Input Data'!E12 -> 7500 | H2: #Opps Required | J2: Sales | K2: Service/Maint | L2: Plumbing | M2: Install
A3: Budgeted Monthly Sales Volume for Break-Even Plus Profit Goal + OH Adjustments Above | B3: ='Sales Goals'!I9 -> 125926.89 | D3: Monthly Installation Sales Goal | F3: =B3*B9 -> 80593.21 | G3: Closing % | H3: ='Input Data'!E13 -> 0.5
D4: # Installations Required this month | F4: =F3/F2 -> 10.745761 | H4: =F4/H3 -> 21.491523 | J4: =H4/'Input Data'!G30 -> 0.39075496 | M4: =F4/'Input Data'!G34 -> 0.4884437
A5: Average Daily Sales Required to Achieve Breakeven + Profit Goal + Overhead Adjustment | B5: =((B3/31)*7)/'Break-even'!C25 -> 5687.0209
D6: Service Opportunity Job Average | F6: ='Input Data'!E16 -> 375 | H6: Opp Calls Required
A7: Sales Volume Break-Even Per Day | B7: =Budget!C36 -> 4885.0544 | D7: Monthly Service Sales Goal | F7: =B3*B11 -> 11333.42 | G7: Closing % | H7: ='Input Data'!E17 -> 1
D8: # Service Tickets Required this month | F8: =F7/F6 -> 30.222454 | H8: =F8/H7 -> 30.222454 | K8: =H8/'Input Data'!G31 -> 0.45791597
A9: Percentage of Revenue for Install | B9: ='Input Data'!E6 -> 0.64
D10: Maintenance Opportunity Job Average | F10: ='Input Data'!E20 -> 125 | H10: Opp Calls Required
A11: Percentage of Revenue for Service | B11: ='Input Data'!E7 -> 0.09 | D11: Monthly Maintenance Sales Goal | F11: =B3*B13 -> 11333.42 | G11: Closing % | H11: ='Input Data'!E21 -> 1
D12: # Maintenance Tickets Required this month | F12: =F11/F10 -> 90.667362 | H12: =F12/H11 -> 90.667362 | K12: =H12/'Input Data'!G32 -> 0.9697044
A13: Percentage of Revenue for Maintenance | B13: ='Input Data'!E8 -> 0.09
D14: Plumbing Opportunity Job Average | F14: ='Input Data'!E24 -> 750 | H14: Opp Calls Required
A15: Percentage of Revenue for Plumbing | B15: ='Input Data'!E9 -> 0.18 | D15: Monthly Service Sales Goal | F15: =B3*B15 -> 22666.84 | G15: Closing % | H15: ='Input Data'!E25 -> 1
D16: # PlumbingTickets Required this month | F16: =F15/F14 -> 30.222454 | H16: =F16/H15 -> 30.222454 | L16: =H16/'Input Data'!G33 -> #DIV/0!
B18: Daily Service Goal | C18: Actual Service Revenue | D18: Daily Install Goal | E18: Actual Install Reveue | F18: Daily Maintenance Goal | G18: Actual Maintenance Revenue | H18: Daily Plumbing Goal | I18: Actual Plumbing Revenue | J18: Sales Goal to Date | K18: Actual Sales to Date | L18: Difference Between Actual Sales & Budgeted Sales
A19: Day 1 | B19: =$B$5*$B$11 -> 511.83188 | C19: 0 | D19: =$B$5*$B$9 -> 3639.6934 | E19: 0 | F19: =$B$5*$B$13 -> 511.83188 | G19: 0 | H19: =$B$5*$B$15 -> 1023.6638 | I19: 0 | J19: =B19+D19+F19+H19 -> 5687.0209 | K19: =C19+E19+G19+I19 -> 0 | L19: =J19-K19 -> 5687.0209
A20: Day 2 | B20: =$B$5*$B$11 -> 511.83188 | C20: 0 | D20: =$B$5*$B$9 -> 3639.6934 | E20: 0 | F20: =$B$5*$B$13 -> 511.83188 | G20: 0 | H20: =$B$5*$B$15 -> 1023.6638 | I20: 0 | J20: =J19+B20+D20+F20+H20 -> 11374.042 | K20: =K19+C20+E20+G20+I20 -> 0 | L20: =J20-K20 -> 11374.042
A21: Day 3 | B21: =$B$5*$B$11 -> 511.83188 | C21: 0 | D21: =$B$5*$B$9 -> 3639.6934 | E21: 0 | F21: =$B$5*$B$13 -> 511.83188 | G21: 0 | H21: =$B$5*$B$15 -> 1023.6638 | I21: 0 | J21: =J20+B21+D21+F21+H21 -> 17061.063 | K21: =K20+C21+E21+G21+I21 -> 0 | L21: =J21-K21 -> 17061.063
A22: Day 4 | B22: =$B$5*$B$11 -> 511.83188 | C22: 0 | D22: =$B$5*$B$9 -> 3639.6934 | E22: 0 | F22: =$B$5*$B$13 -> 511.83188 | G22: 0 | H22: =$B$5*$B$15 -> 1023.6638 | I22: 0 | J22: =J21+B22+D22+F22+H22 -> 22748.084 | K22: =K21+C22+E22+G22+I22 -> 0 | L22: =J22-K22 -> 22748.084
A23: Day 5 | B23: =$B$5*$B$11 -> 511.83188 | C23: 0 | D23: =$B$5*$B$9 -> 3639.6934 | E23: 0 | F23: =$B$5*$B$13 -> 511.83188 | G23: 0 | H23: =$B$5*$B$15 -> 1023.6638 | I23: 0 | J23: =J22+B23+D23+F23+H23 -> 28435.104 | K23: =K22+C23+E23+G23+I23 -> 0 | L23: =J23-K23 -> 28435.104
A24: Day 6 | B24: =$B$5*$B$11 -> 511.83188 | C24: 0 | D24: =$B$5*$B$9 -> 3639.6934 | E24: 0 | F24: =$B$5*$B$13 -> 511.83188 | G24: 0 | H24: =$B$5*$B$15 -> 1023.6638 | I24: 0 | J24: =J23+B24+D24+F24+H24 -> 34122.125 | K24: =K23+C24+E24+G24+I24 -> 0 | L24: =J24-K24 -> 34122.125
A25: Day 7 | B25: =$B$5*$B$11 -> 511.83188 | C25: 0 | D25: =$B$5*$B$9 -> 3639.6934 | E25: 0 | F25: =$B$5*$B$13 -> 511.83188 | G25: 0 | H25: =$B$5*$B$15 -> 1023.6638 | I25: 0 | J25: =J24+B25+D25+F25+H25 -> 39809.146 | K25: =K24+C25+E25+G25+I25 -> 0 | L25: =J25-K25 -> 39809.146
A26: Day 8 | B26: =$B$5*$B$11 -> 511.83188 | C26: 0 | D26: =$B$5*$B$9 -> 3639.6934 | E26: 0 | F26: =$B$5*$B$13 -> 511.83188 | G26: 0 | H26: =$B$5*$B$15 -> 1023.6638 | I26: 0 | J26: =J25+B26+D26+F26+H26 -> 45496.167 | K26: =K25+C26+E26+G26+I26 -> 0 | L26: =J26-K26 -> 45496.167
A27: Day 9 | B27: =$B$5*$B$11 -> 511.83188 | C27: 0 | D27: =$B$5*$B$9 -> 3639.6934 | E27: 0 | F27: =$B$5*$B$13 -> 511.83188 | G27: 0 | H27: =$B$5*$B$15 -> 1023.6638 | I27: 0 | J27: =J26+B27+D27+F27+H27 -> 51183.188 | K27: =K26+C27+E27+G27+I27 -> 0 | L27: =J27-K27 -> 51183.188
A28: Day 10 | B28: =$B$5*$B$11 -> 511.83188 | C28: 0 | D28: =$B$5*$B$9 -> 3639.6934 | E28: 0 | F28: =$B$5*$B$13 -> 511.83188 | G28: 0 | H28: =$B$5*$B$15 -> 1023.6638 | I28: 0 | J28: =J27+B28+D28+F28+H28 -> 56870.209 | K28: =K27+C28+E28+G28+I28 -> 0 | L28: =J28-K28 -> 56870.209
A29: Day 11 | B29: =$B$5*$B$11 -> 511.83188 | C29: 0 | D29: =$B$5*$B$9 -> 3639.6934 | E29: 0 | F29: =$B$5*$B$13 -> 511.83188 | G29: 0 | H29: =$B$5*$B$15 -> 1023.6638 | I29: 0 | J29: =J28+B29+D29+F29+H29 -> 62557.23 | K29: =K28+C29+E29+G29+I29 -> 0 | L29: =J29-K29 -> 62557.23
A30: Day 12 | B30: =$B$5*$B$11 -> 511.83188 | C30: 0 | D30: =$B$5*$B$9 -> 3639.6934 | E30: 0 | F30: =$B$5*$B$13 -> 511.83188 | G30: 0 | H30: =$B$5*$B$15 -> 1023.6638 | I30: 0 | J30: =J29+B30+D30+F30+H30 -> 68244.251 | K30: =K29+C30+E30+G30+I30 -> 0 | L30: =J30-K30 -> 68244.251
A31: Day 13 | B31: =$B$5*$B$11 -> 511.83188 | C31: 0 | D31: =$B$5*$B$9 -> 3639.6934 | E31: 0 | F31: =$B$5*$B$13 -> 511.83188 | G31: 0 | H31: =$B$5*$B$15 -> 1023.6638 | I31: 0 | J31: =J30+B31+D31+F31+H31 -> 73931.272 | K31: =K30+C31+E31+G31+I31 -> 0 | L31: =J31-K31 -> 73931.272
... A45: Day 27 | B45: =$B$5*$B$11 -> 511.83188 | C45: 0 | D45: =$B$5*$B$9 -> 3639.6934 | E45: 0 | F45: =$B$5*$B$13 -> 511.83188 | G45: 0 | H45: =$B$5*$B$15 -> 1023.6638 | I45: 0 | J45: =J44+B45+D45+F45+H45 -> 153549.56 | K45: =K44+C45+E45+G45+I45 -> 0 | L45: =J45-K45 -> 153549.56
A48: ACTION PLANS | C48: Budgeted Cost | D48: Start Date | E48: Completion Date | F48: Who Responsible

Sheet March
A1: Tracking for Daily Break-Even and Sales - March | J1: Field Stafing
D2: Average Installation Ticket | F2: ='Input Data'!F12 -> 6000 | H2: # Opp Required | J2: Sales | K2: Service/Maint | L2: Plumbing | M2: Install
A3: Budgeted Monthly Sales Volume for Break-Even Plus Profit Goal + OH Adjustments Above | B3: ='Sales Goals'!I10 -> 96864.886 | D3: Monthly Installation Sales Goal | F3: =B3*B9 -> 61993.527 | G3: Closing % | H3: ='Input Data'!F13 -> 0.5
D4: # Installations Required this month | F4: =F3/F2 -> 10.332255 | H4: =F4/H3 -> 20.664509 | J4: =H4/'Input Data'!G30 -> 0.37571835 | M4: =F4/'Input Data'!G34 -> 0.46964793
A5: Average Daily Sales Required to Achieve Breakeven + Profit Goal + Overhead Adjustment | B5: =((B3/31)*7)/'Break-even'!C25 -> 4374.5433
D6: Service Opportunity Job Average | F6: ='Input Data'!F16 -> 375 | H6: Opp Calls Required
A7: Sales Volume Break-Even Per Day | B7: =Budget!C36 -> 4885.0544 | D7: Monthly Service Sales Goal | F7: =B3*B11 -> 7749.1909 | G7: Closing % | H7: ='Input Data'!F17 -> 1
D8: # Service Tickets Required this month | F8: =F7/F6 -> 20.664509 | H8: =F8/H7 -> 20.664509 | K8: =H8/'Input Data'!G31 -> 0.31309862
A9: Percentage of Revenue for Install | B9: ='Input Data'!F6 -> 0.64
D10: Maintenance Opportunity Job Average | F10: ='Input Data'!F20 -> 150 | H10: Opp Calls Required
A11: Percentage of Revenue for Service | B11: ='Input Data'!F7 -> 0.08 | D11: Monthly Maintenance Sales Goal | F11: =B3*B13 -> 9686.4886 | G11: Closing % | H11: ='Input Data'!F21 -> 1
D12: # Maintenance Tickets Required this month | F12: =F11/F10 -> 64.576591 | H12: =F12/H11 -> 64.576591 | K12: =H12/'Input Data'!G32 -> 0.69065873
A13: Percentage of Revenue for Maintenance | B13: ='Input Data'!F8 -> 0.1
D14: Plumbing Opportunity Job Average | F14: ='Input Data'!F24 -> 750 | H14: Opp Calls Required
A15: Percentage of Revenue for Plumbing | B15: ='Input Data'!F9 -> 0.18 | D15: Monthly Service Sales Goal | F15: =B3*B15 -> 17435.68 | G15: Closing % | H15: ='Input Data'!F25 -> 1
D16: # PlumbingTickets Required this month | F16: =F15/F14 -> 23.247573 | H16: =F16/H15 -> 23.247573 | L16: =H16/'Input Data'!G33 -> #DIV/0!
B18: Daily Service Goal | C18: Actual Service Revenue | D18: Daily Install Goal | E18: Actual Install Reveue | F18: Daily Maintenance Goal | G18: Actual Maintenance Revenue | H18: Daily Plumbing Goal | I18: Actual Plumbing Revenue | J18: Sales Goal to Date | K18: Actual Sales to Date | L18: Difference Between Actual Sales & Budgeted Sales
A19: Day 1 | B19: =$B$5*$B$11 -> 349.96346 | C19: 0 | D19: =$B$5*$B$9 -> 2799.7077 | E19: 0 | F19: =$B$5*$B$13 -> 437.45433 | G19: 0 | H19: =$B$5*$B$15 -> 787.41779 | I19: 0 | J19: =B19+D19+F19+H19 -> 4374.5433 | K19: =C19+E19+G19+I19 -> 0 | L19: =J19-K19 -> 4374.5433
A20: Day 2 | B20: =$B$5*$B$11 -> 349.96346 | C20: 0 | D20: =$B$5*$B$9 -> 2799.7077 | E20: 0 | F20: =$B$5*$B$13 -> 437.45433 | G20: 0 | H20: =$B$5*$B$15 -> 787.41779 | I20: 0 | J20: =J19+B20+D20+F20+H20 -> 8749.0865 | K20: =K19+C20+E20+G20+I20 -> 0 | L20: =J20-K20 -> 8749.0865
A21: Day 3 | B21: =$B$5*$B$11 -> 349.96346 | C21: 0 | D21: =$B$5*$B$9 -> 2799.7077 | E21: 0 | F21: =$B$5*$B$13 -> 437.45433 | G21: 0 | H21: =$B$5*$B$15 -> 787.41779 | I21: 0 | J21: =J20+B21+D21+F21+H21 -> 13123.63 | K21: =K20+C21+E21+G21+I21 -> 0 | L21: =J21-K21 -> 13123.63
A22: Day 4 | B22: =$B$5*$B$11 -> 349.96346 | C22: 0 | D22: =$B$5*$B$9 -> 2799.7077 | E22: 0 | F22: =$B$5*$B$13 -> 437.45433 | G22: 0 | H22: =$B$5*$B$15 -> 787.41779 | I22: 0 | J22: =J21+B22+D22+F22+H22 -> 17498.173 | K22: =K21+C22+E22+G22+I22 -> 0 | L22: =J22-K22 -> 17498.173
A23: Day 5 | B23: =$B$5*$B$11 -> 349.96346 | C23: 0 | D23: =$B$5*$B$9 -> 2799.7077 | E23: 0 | F23: =$B$5*$B$13 -> 437.45433 | G23: 0 | H23: =$B$5*$B$15 -> 787.41779 | I23: 0 | J23: =J22+B23+D23+F23+H23 -> 21872.716 | K23: =K22+C23+E23+G23+I23 -> 0 | L23: =J23-K23 -> 21872.716
A24: Day 6 | B24: =$B$5*$B$11 -> 349.96346 | C24: 0 | D24: =$B$5*$B$9 -> 2799.7077 | E24: 0 | F24: =$B$5*$B$13 -> 437.45433 | G24: 0 | H24: =$B$5*$B$15 -> 787.41779 | I24: 0 | J24: =J23+B24+D24+F24+H24 -> 26247.26 | K24: =K23+C24+E24+G24+I24 -> 0 | L24: =J24-K24 -> 26247.26
A25: Day 7 | B25: =$B$5*$B$11 -> 349.96346 | C25: 0 | D25: =$B$5*$B$9 -> 2799.7077 | E25: 0 | F25: =$B$5*$B$13 -> 437.45433 | G25: 0 | H25: =$B$5*$B$15 -> 787.41779 | I25: 0 | J25: =J24+B25+D25+F25+H25 -> 30621.803 | K25: =K24+C25+E25+G25+I25 -> 0 | L25: =J25-K25 -> 30621.803
A26: Day 8 | B26: =$B$5*$B$11 -> 349.96346 | C26: 0 | D26: =$B$5*$B$9 -> 2799.7077 | E26: 0 | F26: =$B$5*$B$13 -> 437.45433 | G26: 0 | H26: =$B$5*$B$15 -> 787.41779 | I26: 0 | J26: =J25+B26+D26+F26+H26 -> 34996.346 | K26: =K25+C26+E26+G26+I26 -> 0 | L26: =J26-K26 -> 34996.346
A27: Day 9 | B27: =$B$5*$B$11 -> 349.96346 | C27: 0 | D27: =$B$5*$B$9 -> 2799.7077 | E27: 0 | F27: =$B$5*$B$13 -> 437.45433 | G27: 0 | H27: =$B$5*$B$15 -> 787.41779 | I27: 0 | J27: =J26+B27+D27+F27+H27 -> 39370.889 | K27: =K26+C27+E27+G27+I27 -> 0 | L27: =J27-K27 -> 39370.889
A28: Day 10 | B28: =$B$5*$B$11 -> 349.96346 | C28: 0 | D28: =$B$5*$B$9 -> 2799.7077 | E28: 0 | F28: =$B$5*$B$13 -> 437.45433 | G28: 0 | H28: =$B$5*$B$15 -> 787.41779 | I28: 0 | J28: =J27+B28+D28+F28+H28 -> 43745.433 | K28: =K27+C28+E28+G28+I28 -> 0 | L28: =J28-K28 -> 43745.433
A29: Day 11 | B29: =$B$5*$B$11 -> 349.96346 | C29: 0 | D29: =$B$5*$B$9 -> 2799.7077 | E29: 0 | F29: =$B$5*$B$13 -> 437.45433 | G29: 0 | H29: =$B$5*$B$15 -> 787.41779 | I29: 0 | J29: =J28+B29+D29+F29+H29 -> 48119.976 | K29: =K28+C29+E29+G29+I29 -> 0 | L29: =J29-K29 -> 48119.976
A30: Day 12 | B30: =$B$5*$B$11 -> 349.96346 | C30: 0 | D30: =$B$5*$B$9 -> 2799.7077 | E30: 0 | F30: =$B$5*$B$13 -> 437.45433 | G30: 0 | H30: =$B$5*$B$15 -> 787.41779 | I30: 0 | J30: =J29+B30+D30+F30+H30 -> 52494.519 | K30: =K29+C30+E30+G30+I30 -> 0 | L30: =J30-K30 -> 52494.519
A31: Day 13 | B31: =$B$5*$B$11 -> 349.96346 | C31: 0 | D31: =$B$5*$B$9 -> 2799.7077 | E31: 0 | F31: =$B$5*$B$13 -> 437.45433 | G31: 0 | H31: =$B$5*$B$15 -> 787.41779 | I31: 0 | J31: =J30+B31+D31+F31+H31 -> 56869.062 | K31: =K30+C31+E31+G31+I31 -> 0 | L31: =J31-K31 -> 56869.062
... A45: Day 27 | B45: =$B$5*$B$11 -> 349.96346 | C45: 0 | D45: =$B$5*$B$9 -> 2799.7077 | E45: 0 | F45: =$B$5*$B$13 -> 437.45433 | G45: 0 | H45: =$B$5*$B$15 -> 787.41779 | I45: 0 | J45: =J44+B45+D45+F45+H45 -> 118112.67 | K45: =K44+C45+E45+G45+I45 -> 0 | L45: =J45-K45 -> 118112.67
A48: ACTION PLANS | C48: Budgeted Cost | D48: Start Date | E48: Completion Date | F48: Who Responsible

Sheet April
A1: Tracking for Daily Break-Even and Sales - April | J1: Field Stafing
D2: Average Installation Ticket | F2: ='Input Data'!G12 -> 7500 | H2: # Opp Required | J2: Sales | K2: Service/Maint | L2: Plumbing | M2: Install
A3: Budgeted Monthly Sales Volume for Break-Even Plus Profit Goal + OH Adjustments Above | B3: ='Sales Goals'!I11 -> 188673.19 | D3: Monthly Installation Sales Goal | F3: =B3*B9 -> 120750.84 | G3: Closing % | H3: ='Input Data'!G13 -> 0.5
D4: # Installations Required this month | F4: =F3/F2 -> 16.100112 | H4: =F4/H3 -> 32.200224 | J4: =H4/'Input Data'!G30 -> 0.58545862 | M4: =F4/'Input Data'!G34 -> 0.73182327
A5: Average Daily Sales Required to Achieve Breakeven + Profit Goal + Overhead Adjustment | B5: =((B3/31)*7)/'Break-even'!C25 -> 8520.7246
D6: Service Opportunity Job Average | F6: ='Input Data'!G16 -> 400 | H6: Opp Calls Required
A7: Sales Volume Break-Even Per Day | B7: =Budget!C36 -> 4885.0544 | D7: Monthly Service Sales Goal | F7: =B3*B11 -> 18867.319 | G7: Closing % | H7: ='Input Data'!G17 -> 1
D8: # Service Tickets Required this month | F8: =F7/F6 -> 47.168297 | H8: =F8/H7 -> 47.168297 | K8: =H8/'Input Data'!G31 -> 0.71467116
A9: Percentage of Revenue for Install | B9: ='Input Data'!G6 -> 0.64
D10: Maintenance Opportunity Job Average | F10: ='Input Data'!G20 -> 150 | H10: Opp Calls Required
A11: Percentage of Revenue for Service | B11: ='Input Data'!G7 -> 0.1 | D11: Monthly Maintenance Sales Goal | F11: =B3*B13 -> 15093.855 | G11: Closing % | H11: ='Input Data'!G21 -> 1
D12: # Maintenance Tickets Required this month | F12: =F11/F10 -> 100.6257 | H12: =F12/H11 -> 100.6257 | K12: =H12/'Input Data'!G32 -> 1.0762107
A13: Percentage of Revenue for Maintenance | B13: ='Input Data'!G8 -> 0.08
D14: Plumbing Opportunity Job Average | F14: ='Input Data'!G24 -> 750 | H14: Opp Calls Required
A15: Percentage of Revenue for Plumbing | B15: ='Input Data'!G9 -> 0.18 | D15: Monthly Service Sales Goal | F15: =B3*B15 -> 33961.174 | G15: Closing % | H15: ='Input Data'!G25 -> 1
D16: # PlumbingTickets Required this month | F16: =F15/F14 -> 45.281565 | H16: =F16/H15 -> 45.281565 | L16: =H16/'Input Data'!G33 -> #DIV/0!
B18: Daily Service Goal | C18: Actual Service Revenue | D18: Daily Install Goal | E18: Actual Install Reveue | F18: Daily Maintenance Goal | G18: Actual Maintenance Revenue | H18: Daily Plumbing Goal | I18: Actual Plumbing Revenue | J18: Sales Goal to Date | K18: Actual Sales to Date | L18: Difference Between Actual Sales & Budgeted Sales
A19: Day 1 | B19: =$B$5*$B$11 -> 852.07246 | C19: 0 | D19: =$B$5*$B$9 -> 5453.2637 | E19: 0 | F19: =$B$5*$B$13 -> 681.65797 | G19: 0 | H19: =$B$5*$B$15 -> 1533.7304 | I19: 0 | J19: =B19+D19+F19+H19 -> 8520.7246 | K19: =C19+E19+G19+I19 -> 0 | L19: =J19-K19 -> 8520.7246
A20: Day 2 | B20: =$B$5*$B$11 -> 852.07246 | C20: 0 | D20: =$B$5*$B$9 -> 5453.2637 | E20: 0 | F20: =$B$5*$B$13 -> 681.65797 | G20: 0 | H20: =$B$5*$B$15 -> 1533.7304 | I20: 0 | J20: =J19+B20+D20+F20+H20 -> 17041.449 | K20: =K19+C20+E20+G20+I20 -> 0 | L20: =J20-K20 -> 17041.449
A21: Day 3 | B21: =$B$5*$B$11 -> 852.07246 | C21: 0 | D21: =$B$5*$B$9 -> 5453.2637 | E21: 0 | F21: =$B$5*$B$13 -> 681.65797 | G21: 0 | H21: =$B$5*$B$15 -> 1533.7304 | I21: 0 | J21: =J20+B21+D21+F21+H21 -> 25562.174 | K21: =K20+C21+E21+G21+I21 -> 0 | L21: =J21-K21 -> 25562.174
A22: Day 4 | B22: =$B$5*$B$11 -> 852.07246 | C22: 0 | D22: =$B$5*$B$9 -> 5453.2637 | E22: 0 | F22: =$B$5*$B$13 -> 681.65797 | G22: 0 | H22: =$B$5*$B$15 -> 1533.7304 | I22: 0 | J22: =J21+B22+D22+F22+H22 -> 34082.898 | K22: =K21+C22+E22+G22+I22 -> 0 | L22: =J22-K22 -> 34082.898
A23: Day 5 | B23: =$B$5*$B$11 -> 852.07246 | C23: 0 | D23: =$B$5*$B$9 -> 5453.2637 | E23: 0 | F23: =$B$5*$B$13 -> 681.65797 | G23: 0 | H23: =$B$5*$B$15 -> 1533.7304 | I23: 0 | J23: =J22+B23+D23+F23+H23 -> 42603.623 | K23: =K22+C23+E23+G23+I23 -> 0 | L23: =J23-K23 -> 42603.623
A24: Day 6 | B24: =$B$5*$B$11 -> 852.07246 | C24: 0 | D24: =$B$5*$B$9 -> 5453.2637 | E24: 0 | F24: =$B$5*$B$13 -> 681.65797 | G24: 0 | H24: =$B$5*$B$15 -> 1533.7304 | I24: 0 | J24: =J23+B24+D24+F24+H24 -> 51124.347 | K24: =K23+C24+E24+G24+I24 -> 0 | L24: =J24-K24 -> 51124.347
A25: Day 7 | B25: =$B$5*$B$11 -> 852.07246 | C25: 0 | D25: =$B$5*$B$9 -> 5453.2637 | E25: 0 | F25: =$B$5*$B$13 -> 681.65797 | G25: 0 | H25: =$B$5*$B$15 -> 1533.7304 | I25: 0 | J25: =J24+B25+D25+F25+H25 -> 59645.072 | K25: =K24+C25+E25+G25+I25 -> 0 | L25: =J25-K25 -> 59645.072
A26: Day 8 | B26: =$B$5*$B$11 -> 852.07246 | C26: 0 | D26: =$B$5*$B$9 -> 5453.2637 | E26: 0 | F26: =$B$5*$B$13 -> 681.65797 | G26: 0 | H26: =$B$5*$B$15 -> 1533.7304 | I26: 0 | J26: =J25+B26+D26+F26+H26 -> 68165.797 | K26: =K25+C26+E26+G26+I26 -> 0 | L26: =J26-K26 -> 68165.797
A27: Day 9 | B27: =$B$5*$B$11 -> 852.07246 | C27: 0 | D27: =$B$5*$B$9 -> 5453.2637 | E27: 0 | F27: =$B$5*$B$13 -> 681.65797 | G27: 0 | H27: =$B$5*$B$15 -> 1533.7304 | I27: 0 | J27: =J26+B27+D27+F27+H27 -> 76686.521 | K27: =K26+C27+E27+G27+I27 -> 0 | L27: =J27-K27 -> 76686.521
A28: Day 10 | B28: =$B$5*$B$11 -> 852.07246 | C28: 0 | D28: =$B$5*$B$9 -> 5453.2637 | E28: 0 | F28: =$B$5*$B$13 -> 681.65797 | G28: 0 | H28: =$B$5*$B$15 -> 1533.7304 | I28: 0 | J28: =J27+B28+D28+F28+H28 -> 85207.246 | K28: =K27+C28+E28+G28+I28 -> 0 | L28: =J28-K28 -> 85207.246
A29: Day 11 | B29: =$B$5*$B$11 -> 852.07246 | C29: 0 | D29: =$B$5*$B$9 -> 5453.2637 | E29: 0 | F29: =$B$5*$B$13 -> 681.65797 | G29: 0 | H29: =$B$5*$B$15 -> 1533.7304 | I29: 0 | J29: =J28+B29+D29+F29+H29 -> 93727.97 | K29: =K28+C29+E29+G29+I29 -> 0 | L29: =J29-K29 -> 93727.97
A30: Day 12 | B30: =$B$5*$B$11 -> 852.07246 | C30: 0 | D30: =$B$5*$B$9 -> 5453.2637 | E30: 0 | F30: =$B$5*$B$13 -> 681.65797 | G30: 0 | H30: =$B$5*$B$15 -> 1533.7304 | I30: 0 | J30: =J29+B30+D30+F30+H30 -> 102248.69 | K30: =K29+C30+E30+G30+I30 -> 0 | L30: =J30-K30 -> 102248.69
A31: Day 13 | B31: =$B$5*$B$11 -> 852.07246 | C31: 0 | D31: =$B$5*$B$9 -> 5453.2637 | E31: 0 | F31: =$B$5*$B$13 -> 681.65797 | G31: 0 | H31: =$B$5*$B$15 -> 1533.7304 | I31: 0 | J31: =J30+B31+D31+F31+H31 -> 110769.42 | K31: =K30+C31+E31+G31+I31 -> 0 | L31: =J31-K31 -> 110769.42
... A45: Day 27 | B45: =$B$5*$B$11 -> 852.07246 | C45: 0 | D45: =$B$5*$B$9 -> 5453.2637 | E45: 0 | F45: =$B$5*$B$13 -> 681.65797 | G45: 0 | H45: =$B$5*$B$15 -> 1533.7304 | I45: 0 | J45: =J44+B45+D45+F45+H45 -> 230059.56 | K45: =K44+C45+E45+G45+I45 -> 0 | L45: =J45-K45 -> 230059.56
A48: ACTION PLANS | C48: Budgeted Cost | D48: Start Date | E48: Completion Date | F48: Who Responsible

Sheet May
A1: Tracking for Daily Break-Even and Sales - May | J1: Field Stafing
D2: Average Installation Ticket | F2: ='Input Data'!H12 -> 10000 | H2: # Opp Required | J2: Sales | K2: Service/Maint | L2: Plumbing | M2: Install
A3: Budgeted Monthly Sales Volume for Break-Even Plus Profit Goal + OH Adjustments Above | B3: ='Sales Goals'!I12 -> 193952.49 | D3: Monthly Installation Sales Goal | F3: =B3*B9 -> 124129.59 | G3: Closing % | H3: ='Input Data'!H13 -> 0.5
D4: # Installations Required this month | F4: =F3/F2 -> 12.412959 | H4: =F4/H3 -> 24.825919 | J4: =H4/'Input Data'!G30 -> 0.45138034 | M4: =F4/'Input Data'!G34 -> 0.56422543
A5: Average Daily Sales Required to Achieve Breakeven + Profit Goal + Overhead Adjustment | B5: =((B3/31)*7)/'Break-even'!C25 -> 8759.1447
D6: Service Opportunity Job Average | F6: ='Input Data'!H16 -> 450 | H6: Opp Calls Required
A7: Sales Volume Break-Even Per Day | B7: =Budget!C36 -> 4885.0544 | D7: Monthly Service Sales Goal | F7: =B3*B11 -> 25213.824 | G7: Closing % | H7: ='Input Data'!H17 -> 1
D8: # Service Tickets Required this month | F8: =F7/F6 -> 56.030719 | H8: =F8/H7 -> 56.030719 | K8: =H8/'Input Data'!G31 -> 0.84895029
A9: Percentage of Revenue for Install | B9: ='Input Data'!H6 -> 0.64
D10: Maintenance Opportunity Job Average | F10: ='Input Data'!H20 -> 200 | H10: Opp Calls Required
A11: Percentage of Revenue for Service | B11: ='Input Data'!H7 -> 0.13 | D11: Monthly Maintenance Sales Goal | F11: =B3*B13 -> 9697.6245 | G11: Closing % | H11: ='Input Data'!H21 -> 1
D12: # Maintenance Tickets Required this month | F12: =F11/F10 -> 48.488123 | H12: =F12/H11 -> 48.488123 | K12: =H12/'Input Data'!G32 -> 0.51858955
A13: Percentage of Revenue for Maintenance | B13: ='Input Data'!H8 -> 0.05
D14: Plumbing Opportunity Job Average | F14: ='Input Data'!H24 -> 750 | H14: Opp Calls Required
A15: Percentage of Revenue for Plumbing | B15: ='Input Data'!H9 -> 0.18 | D15: Monthly Service Sales Goal | F15: =B3*B15 -> 34911.448 | G15: Closing % | H15: ='Input Data'!H25 -> 1
D16: # PlumbingTickets Required this month | F16: =F15/F14 -> 46.548598 | H16: =F16/H15 -> 46.548598 | L16: =H16/'Input Data'!G33 -> #DIV/0!
B18: Daily Service Goal | C18: Actual Service Revenue | D18: Daily Install Goal | E18: Actual Install Reveue | F18: Daily Maintenance Goal | G18: Actual Maintenance Revenue | H18: Daily Plumbing Goal | I18: Actual Plumbing Revenue | J18: Sales Goal to Date | K18: Actual Sales to Date | L18: Difference Between Actual Sales & Budgeted Sales
A19: Day 1 | B19: =$B$5*$B$11 -> 1138.6888 | C19: 0 | D19: =$B$5*$B$9 -> 5605.8526 | E19: 0 | F19: =$B$5*$B$13 -> 437.95724 | G19: 0 | H19: =$B$5*$B$15 -> 1576.6461 | I19: 0 | J19: =B19+D19+F19+H19 -> 8759.1447 | K19: =C19+E19+G19+I19 -> 0 | L19: =J19-K19 -> 8759.1447
A20: Day 2 | B20: =$B$5*$B$11 -> 1138.6888 | C20: 0 | D20: =$B$5*$B$9 -> 5605.8526 | E20: 0 | F20: =$B$5*$B$13 -> 437.95724 | G20: 0 | H20: =$B$5*$B$15 -> 1576.6461 | I20: 0 | J20: =J19+B20+D20+F20+H20 -> 17518.289 | K20: =K19+C20+E20+G20+I20 -> 0 | L20: =J20-K20 -> 17518.289
A21: Day 3 | B21: =$B$5*$B$11 -> 1138.6888 | C21: 0 | D21: =$B$5*$B$9 -> 5605.8526 | E21: 0 | F21: =$B$5*$B$13 -> 437.95724 | G21: 0 | H21: =$B$5*$B$15 -> 1576.6461 | I21: 0 | J21: =J20+B21+D21+F21+H21 -> 26277.434 | K21: =K20+C21+E21+G21+I21 -> 0 | L21: =J21-K21 -> 26277.434
A22: Day 4 | B22: =$B$5*$B$11 -> 1138.6888 | C22: 0 | D22: =$B$5*$B$9 -> 5605.8526 | E22: 0 | F22: =$B$5*$B$13 -> 437.95724 | G22: 0 | H22: =$B$5*$B$15 -> 1576.6461 | I22: 0 | J22: =J21+B22+D22+F22+H22 -> 35036.579 | K22: =K21+C22+E22+G22+I22 -> 0 | L22: =J22-K22 -> 35036.579
A23: Day 5 | B23: =$B$5*$B$11 -> 1138.6888 | C23: 0 | D23: =$B$5*$B$9 -> 5605.8526 | E23: 0 | F23: =$B$5*$B$13 -> 437.95724 | G23: 0 | H23: =$B$5*$B$15 -> 1576.6461 | I23: 0 | J23: =J22+B23+D23+F23+H23 -> 43795.724 | K23: =K22+C23+E23+G23+I23 -> 0 | L23: =J23-K23 -> 43795.724
A24: Day 6 | B24: =$B$5*$B$11 -> 1138.6888 | C24: 0 | D24: =$B$5*$B$9 -> 5605.8526 | E24: 0 | F24: =$B$5*$B$13 -> 437.95724 | G24: 0 | H24: =$B$5*$B$15 -> 1576.6461 | I24: 0 | J24: =J23+B24+D24+F24+H24 -> 52554.868 | K24: =K23+C24+E24+G24+I24 -> 0 | L24: =J24-K24 -> 52554.868
A25: Day 7 | B25: =$B$5*$B$11 -> 1138.6888 | C25: 0 | D25: =$B$5*$B$9 -> 5605.8526 | E25: 0 | F25: =$B$5*$B$13 -> 437.95724 | G25: 0 | H25: =$B$5*$B$15 -> 1576.6461 | I25: 0 | J25: =J24+B25+D25+F25+H25 -> 61314.013 | K25: =K24+C25+E25+G25+I25 -> 0 | L25: =J25-K25 -> 61314.013
A26: Day 8 | B26: =$B$5*$B$11 -> 1138.6888 | C26: 0 | D26: =$B$5*$B$9 -> 5605.8526 | E26: 0 | F26: =$B$5*$B$13 -> 437.95724 | G26: 0 | H26: =$B$5*$B$15 -> 1576.6461 | I26: 0 | J26: =J25+B26+D26+F26+H26 -> 70073.158 | K26: =K25+C26+E26+G26+I26 -> 0 | L26: =J26-K26 -> 70073.158
A27: Day 9 | B27: =$B$5*$B$11 -> 1138.6888 | C27: 0 | D27: =$B$5*$B$9 -> 5605.8526 | E27: 0 | F27: =$B$5*$B$13 -> 437.95724 | G27: 0 | H27: =$B$5*$B$15 -> 1576.6461 | I27: 0 | J27: =J26+B27+D27+F27+H27 -> 78832.303 | K27: =K26+C27+E27+G27+I27 -> 0 | L27: =J27-K27 -> 78832.303
A28: Day 10 | B28: =$B$5*$B$11 -> 1138.6888 | C28: 0 | D28: =$B$5*$B$9 -> 5605.8526 | E28: 0 | F28: =$B$5*$B$13 -> 437.95724 | G28: 0 | H28: =$B$5*$B$15 -> 1576.6461 | I28: 0 | J28: =J27+B28+D28+F28+H28 -> 87591.447 | K28: =K27+C28+E28+G28+I28 -> 0 | L28: =J28-K28 -> 87591.447
A29: Day 11 | B29: =$B$5*$B$11 -> 1138.6888 | C29: 0 | D29: =$B$5*$B$9 -> 5605.8526 | E29: 0 | F29: =$B$5*$B$13 -> 437.95724 | G29: 0 | H29: =$B$5*$B$15 -> 1576.6461 | I29: 0 | J29: =J28+B29+D29+F29+H29 -> 96350.592 | K29: =K28+C29+E29+G29+I29 -> 0 | L29: =J29-K29 -> 96350.592
A30: Day 12 | B30: =$B$5*$B$11 -> 1138.6888 | C30: 0 | D30: =$B$5*$B$9 -> 5605.8526 | E30: 0 | F30: =$B$5*$B$13 -> 437.95724 | G30: 0 | H30: =$B$5*$B$15 -> 1576.6461 | I30: 0 | J30: =J29+B30+D30+F30+H30 -> 105109.74 | K30: =K29+C30+E30+G30+I30 -> 0 | L30: =J30-K30 -> 105109.74
A31: Day 13 | B31: =$B$5*$B$11 -> 1138.6888 | C31: 0 | D31: =$B$5*$B$9 -> 5605.8526 | E31: 0 | F31: =$B$5*$B$13 -> 437.95724 | G31: 0 | H31: =$B$5*$B$15 -> 1576.6461 | I31: 0 | J31: =J30+B31+D31+F31+H31 -> 113868.88 | K31: =K30+C31+E31+G31+I31 -> 0 | L31: =J31-K31 -> 113868.88
... A45: Day 27 | B45: =$B$5*$B$11 -> 1138.6888 | C45: 0 | D45: =$B$5*$B$9 -> 5605.8526 | E45: 0 | F45: =$B$5*$B$13 -> 437.95724 | G45: 0 | H45: =$B$5*$B$15 -> 1576.6461 | I45: 0 | J45: =J44+B45+D45+F45+H45 -> 236496.91 | K45: =K44+C45+E45+G45+I45 -> 0 | L45: =J45-K45 -> 236496.91
A48: ACTION PLANS | C48: Budgeted Cost | D48: Start Date | E48: Completion Date | F48: Who Responsible

Sheet June
A1: Tracking for Daily Break-Even and Sales - June | J1: Field Stafing
D2: Average Installation Ticket | F2: ='Input Data'!I12 -> 9000 | H2: # Opp Required | J2: Sales | K2: Service/Maint | L2: Plumbing | M2: Install
A3: Budgeted Monthly Sales Volume for Break-Even Plus Profit Goal + OH Adjustments Above | B3: ='Sales Goals'!I13 -> 211612.23 | D3: Monthly Installation Sales Goal | F3: =B3*B9 -> 135431.83 | G3: Closing % | H3: ='Input Data'!I13 -> 0.5
D4: # Installations Required this month | F4: =F3/F2 -> 15.047981 | H4: =F4/H3 -> 30.095962 | J4: =H4/'Input Data'!G30 -> 0.54719931 | M4: =F4/'Input Data'!G34 -> 0.68399914
A5: Average Daily Sales Required to Achieve Breakeven + Profit Goal + Overhead Adjustment | B5: =((B3/31)*7)/'Break-even'!C25 -> 9556.6815
D6: Service Opportunity Job Average | F6: ='Input Data'!I16 -> 450 | H6: Opp Calls Required
A7: Sales Volume Break-Even Per Day | B7: =Budget!C36 -> 4885.0544 | D7: Monthly Service Sales Goal | F7: =B3*B11 -> 27509.59 | G7: Closing % | H7: ='Input Data'!I17 -> 1
D8: # Service Tickets Required this month | F8: =F7/F6 -> 61.132423 | H8: =F8/H7 -> 61.132423 | K8: =H8/'Input Data'!G31 -> 0.92624883
A9: Percentage of Revenue for Install | B9: ='Input Data'!I6 -> 0.64
D10: Maintenance Opportunity Job Average | F10: ='Input Data'!I20 -> 200 | H10: Opp Calls Required
A11: Percentage of Revenue for Service | B11: ='Input Data'!I7 -> 0.13 | D11: Monthly Maintenance Sales Goal | F11: =B3*B13 -> 10580.612 | G11: Closing % | H11: ='Input Data'!I21 -> 1
D12: # Maintenance Tickets Required this month | F12: =F11/F10 -> 52.903058 | H12: =F12/H11 -> 52.903058 | K12: =H12/'Input Data'!G32 -> 0.56580811
A13: Percentage of Revenue for Maintenance | B13: ='Input Data'!I8 -> 0.05
D14: Plumbing Opportunity Job Average | F14: ='Input Data'!I24 -> 750 | H14: Opp Calls Required
A15: Percentage of Revenue for Plumbing | B15: ='Input Data'!I9 -> 0.18 | D15: Monthly Service Sales Goal | F15: =B3*B15 -> 38090.202 | G15: Closing % | H15: ='Input Data'!I25 -> 1
D16: # PlumbingTickets Required this month | F16: =F15/F14 -> 50.786936 | H16: =F16/H15 -> 50.786936 | L16: =H16/'Input Data'!G33 -> #DIV/0!
B18: Daily Service Goal | C18: Actual Service Revenue | D18: Daily Install Goal | E18: Actual Install Reveue | F18: Daily Maintenance Goal | G18: Actual Maintenance Revenue | H18: Daily Plumbing Goal | I18: Actual Plumbing Revenue | J18: Sales Goal to Date | K18: Actual Sales to Date | L18: Difference Between Actual Sales & Budgeted Sales
A19: Day 1 | B19: =$B$5*$B$11 -> 1242.3686 | C19: 0 | D19: =$B$5*$B$9 -> 6116.2762 | E19: 0 | F19: =$B$5*$B$13 -> 477.83407 | G19: 0 | H19: =$B$5*$B$15 -> 1720.2027 | I19: 0 | J19: =B19+D19+F19+H19 -> 9556.6815 | K19: =C19+E19+G19+I19 -> 0 | L19: =J19-K19 -> 9556.6815
A20: Day 2 | B20: =$B$5*$B$11 -> 1242.3686 | C20: 0 | D20: =$B$5*$B$9 -> 6116.2762 | E20: 0 | F20: =$B$5*$B$13 -> 477.83407 | G20: 0 | H20: =$B$5*$B$15 -> 1720.2027 | I20: 0 | J20: =J19+B20+D20+F20+H20 -> 19113.363 | K20: =K19+C20+E20+G20+I20 -> 0 | L20: =J20-K20 -> 19113.363
A21: Day 3 | B21: =$B$5*$B$11 -> 1242.3686 | C21: 0 | D21: =$B$5*$B$9 -> 6116.2762 | E21: 0 | F21: =$B$5*$B$13 -> 477.83407 | G21: 0 | H21: =$B$5*$B$15 -> 1720.2027 | I21: 0 | J21: =J20+B21+D21+F21+H21 -> 28670.044 | K21: =K20+C21+E21+G21+I21 -> 0 | L21: =J21-K21 -> 28670.044
A22: Day 4 | B22: =$B$5*$B$11 -> 1242.3686 | C22: 0 | D22: =$B$5*$B$9 -> 6116.2762 | E22: 0 | F22: =$B$5*$B$13 -> 477.83407 | G22: 0 | H22: =$B$5*$B$15 -> 1720.2027 | I22: 0 | J22: =J21+B22+D22+F22+H22 -> 38226.726 | K22: =K21+C22+E22+G22+I22 -> 0 | L22: =J22-K22 -> 38226.726
A23: Day 5 | B23: =$B$5*$B$11 -> 1242.3686 | C23: 0 | D23: =$B$5*$B$9 -> 6116.2762 | E23: 0 | F23: =$B$5*$B$13 -> 477.83407 | G23: 0 | H23: =$B$5*$B$15 -> 1720.2027 | I23: 0 | J23: =J22+B23+D23+F23+H23 -> 47783.407 | K23: =K22+C23+E23+G23+I23 -> 0 | L23: =J23-K23 -> 47783.407
A24: Day 6 | B24: =$B$5*$B$11 -> 1242.3686 | C24: 0 | D24: =$B$5*$B$9 -> 6116.2762 | E24: 0 | F24: =$B$5*$B$13 -> 477.83407 | G24: 0 | H24: =$B$5*$B$15 -> 1720.2027 | I24: 0 | J24: =J23+B24+D24+F24+H24 -> 57340.089 | K24: =K23+C24+E24+G24+I24 -> 0 | L24: =J24-K24 -> 57340.089
A25: Day 7 | B25: =$B$5*$B$11 -> 1242.3686 | C25: 0 | D25: =$B$5*$B$9 -> 6116.2762 | E25: 0 | F25: =$B$5*$B$13 -> 477.83407 | G25: 0 | H25: =$B$5*$B$15 -> 1720.2027 | I25: 0 | J25: =J24+B25+D25+F25+H25 -> 66896.77 | K25: =K24+C25+E25+G25+I25 -> 0 | L25: =J25-K25 -> 66896.77
A26: Day 8 | B26: =$B$5*$B$11 -> 1242.3686 | C26: 0 | D26: =$B$5*$B$9 -> 6116.2762 | E26: 0 | F26: =$B$5*$B$13 -> 477.83407 | G26: 0 | H26: =$B$5*$B$15 -> 1720.2027 | I26: 0 | J26: =J25+B26+D26+F26+H26 -> 76453.452 | K26: =K25+C26+E26+G26+I26 -> 0 | L26: =J26-K26 -> 76453.452
A27: Day 9 | B27: =$B$5*$B$11 -> 1242.3686 | C27: 0 | D27: =$B$5*$B$9 -> 6116.2762 | E27: 0 | F27: =$B$5*$B$13 -> 477.83407 | G27: 0 | H27: =$B$5*$B$15 -> 1720.2027 | I27: 0 | J27: =J26+B27+D27+F27+H27 -> 86010.133 | K27: =K26+C27+E27+G27+I27 -> 0 | L27: =J27-K27 -> 86010.133
A28: Day 10 | B28: =$B$5*$B$11 -> 1242.3686 | C28: 0 | D28: =$B$5*$B$9 -> 6116.2762 | E28: 0 | F28: =$B$5*$B$13 -> 477.83407 | G28: 0 | H28: =$B$5*$B$15 -> 1720.2027 | I28: 0 | J28: =J27+B28+D28+F28+H28 -> 95566.815 | K28: =K27+C28+E28+G28+I28 -> 0 | L28: =J28-K28 -> 95566.815
A29: Day 11 | B29: =$B$5*$B$11 -> 1242.3686 | C29: 0 | D29: =$B$5*$B$9 -> 6116.2762 | E29: 0 | F29: =$B$5*$B$13 -> 477.83407 | G29: 0 | H29: =$B$5*$B$15 -> 1720.2027 | I29: 0 | J29: =J28+B29+D29+F29+H29 -> 105123.5 | K29: =K28+C29+E29+G29+I29 -> 0 | L29: =J29-K29 -> 105123.5
A30: Day 12 | B30: =$B$5*$B$11 -> 1242.3686 | C30: 0 | D30: =$B$5*$B$9 -> 6116.2762 | E30: 0 | F30: =$B$5*$B$13 -> 477.83407 | G30: 0 | H30: =$B$5*$B$15 -> 1720.2027 | I30: 0 | J30: =J29+B30+D30+F30+H30 -> 114680.18 | K30: =K29+C30+E30+G30+I30 -> 0 | L30: =J30-K30 -> 114680.18
A31: Day 13 | B31: =$B$5*$B$11 -> 1242.3686 | C31: 0 | D31: =$B$5*$B$9 -> 6116.2762 | E31: 0 | F31: =$B$5*$B$13 -> 477.83407 | G31: 0 | H31: =$B$5*$B$15 -> 1720.2027 | I31: 0 | J31: =J30+B31+D31+F31+H31 -> 124236.86 | K31: =K30+C31+E31+G31+I31 -> 0 | L31: =J31-K31 -> 124236.86
... A45: Day 27 | B45: =$B$5*$B$11 -> 1242.3686 | C45: 0 | D45: =$B$5*$B$9 -> 6116.2762 | E45: 0 | F45: =$B$5*$B$13 -> 477.83407 | G45: 0 | H45: =$B$5*$B$15 -> 1720.2027 | I45: 0 | J45: =J44+B45+D45+F45+H45 -> 258030.4 | K45: =K44+C45+E45+G45+I45 -> 0 | L45: =J45-K45 -> 258030.4
A48: ACTION PLANS | C48: Budgeted Cost | D48: Start Date | E48: Completion Date | F48: Who Responsible

Sheet July
A1: Tracking for Daily Break-Even and Sales - July | J1: Field Stafing
D2: Average Installation Ticket | F2: ='Input Data'!J12 -> 8500 | H2: # Opp Required | J2: Sales | K2: Service/Maint | L2: Plumbing | M2: Install
A3: Budgeted Monthly Sales Volume for Break-Even Plus Profit Goal + OH Adjustments Above | B3: ='Sales Goals'!I14 -> 267666.3 | D3: Monthly Installation Sales Goal | F3: =B3*B9 -> 171306.43 | G3: Closing % | H3: ='Input Data'!J13 -> 0.5
D4: # Installations Required this month | F4: =F3/F2 -> 20.153698 | H4: =F4/H3 -> 40.307396 | J4: =H4/'Input Data'!G30 -> 0.73286175 | M4: =F4/'Input Data'!G34 -> 0.91607719
A5: Average Daily Sales Required to Achieve Breakeven + Profit Goal + Overhead Adjustment | B5: =((B3/31)*7)/'Break-even'!C25 -> 12088.156
D6: Service Opportunity Job Average | F6: ='Input Data'!J16 -> 425 | H6: Opp Calls Required
A7: Sales Volume Break-Even Per Day | B7: =Budget!C36 -> 4885.0544 | D7: Monthly Service Sales Goal | F7: =B3*B11 -> 32119.956 | G7: Closing % | H7: ='Input Data'!J17 -> 1
D8: # Service Tickets Required this month | F8: =F7/F6 -> 75.576368 | H8: =F8/H7 -> 75.576368 | K8: =H8/'Input Data'!G31 -> 1.1450965
A9: Percentage of Revenue for Install | B9: ='Input Data'!J6 -> 0.64
D10: Maintenance Opportunity Job Average | F10: ='Input Data'!J20 -> 200 | H10: Opp Calls Required
A11: Percentage of Revenue for Service | B11: ='Input Data'!J7 -> 0.12 | D11: Monthly Maintenance Sales Goal | F11: =B3*B13 -> 16059.978 | G11: Closing % | H11: ='Input Data'!J21 -> 1
D12: # Maintenance Tickets Required this month | F12: =F11/F10 -> 80.299891 | H12: =F12/H11 -> 80.299891 | K12: =H12/'Input Data'!G32 -> 0.85882236
A13: Percentage of Revenue for Maintenance | B13: ='Input Data'!J8 -> 0.06
D14: Plumbing Opportunity Job Average | F14: ='Input Data'!J24 -> 750 | H14: Opp Calls Required
A15: Percentage of Revenue for Plumbing | B15: ='Input Data'!J9 -> 0.18 | D15: Monthly Service Sales Goal | F15: =B3*B15 -> 48179.935 | G15: Closing % | H15: ='Input Data'!J25 -> 1
D16: # PlumbingTickets Required this month | F16: =F15/F14 -> 64.239913 | H16: =F16/H15 -> 64.239913 | L16: =H16/'Input Data'!G33 -> #DIV/0!
B18: Daily Service Goal | C18: Actual Service Revenue | D18: Daily Install Goal | E18: Actual Install Reveue | F18: Daily Maintenance Goal | G18: Actual Maintenance Revenue | H18: Daily Plumbing Goal | I18: Actual Plumbing Revenue | J18: Sales Goal to Date | K18: Actual Sales to Date | L18: Difference Between Actual Sales & Budgeted Sales
A19: Day 1 | B19: =$B$5*$B$11 -> 1450.5787 | C19: 0 | D19: =$B$5*$B$9 -> 7736.4196 | E19: 0 | F19: =$B$5*$B$13 -> 725.28934 | G19: 0 | H19: =$B$5*$B$15 -> 2175.868 | I19: 0 | J19: =B19+D19+F19+H19 -> 12088.156 | K19: =C19+E19+G19+I19 -> 0 | L19: =J19-K19 -> 12088.156
A20: Day 2 | B20: =$B$5*$B$11 -> 1450.5787 | C20: 0 | D20: =$B$5*$B$9 -> 7736.4196 | E20: 0 | F20: =$B$5*$B$13 -> 725.28934 | G20: 0 | H20: =$B$5*$B$15 -> 2175.868 | I20: 0 | J20: =J19+B20+D20+F20+H20 -> 24176.311 | K20: =K19+C20+E20+G20+I20 -> 0 | L20: =J20-K20 -> 24176.311
A21: Day 3 | B21: =$B$5*$B$11 -> 1450.5787 | C21: 0 | D21: =$B$5*$B$9 -> 7736.4196 | E21: 0 | F21: =$B$5*$B$13 -> 725.28934 | G21: 0 | H21: =$B$5*$B$15 -> 2175.868 | I21: 0 | J21: =J20+B21+D21+F21+H21 -> 36264.467 | K21: =K20+C21+E21+G21+I21 -> 0 | L21: =J21-K21 -> 36264.467
A22: Day 4 | B22: =$B$5*$B$11 -> 1450.5787 | C22: 0 | D22: =$B$5*$B$9 -> 7736.4196 | E22: 0 | F22: =$B$5*$B$13 -> 725.28934 | G22: 0 | H22: =$B$5*$B$15 -> 2175.868 | I22: 0 | J22: =J21+B22+D22+F22+H22 -> 48352.622 | K22: =K21+C22+E22+G22+I22 -> 0 | L22: =J22-K22 -> 48352.622
